iadsstgapphost01
*** Found local files:
***   * Airflow/logs/dag_id=A4_COG_Generator_Worker/run_id=scheduled__2024-09-27T05:20:00+00:00/task_id=cog_generator_sub_worker/map_index=0/attempt=1.log
[2024-09-27T06:17:08.672+0000] {taskinstance.py:1159} INFO - Dependencies all met for dep_context=non-requeueable deps ti=<TaskInstance: A4_COG_Generator_Worker.cog_generator_sub_worker scheduled__2024-09-27T05:20:00+00:00 map_index=0 [queued]>
[2024-09-27T06:17:08.682+0000] {taskinstance.py:1159} INFO - Dependencies all met for dep_context=requeueable deps ti=<TaskInstance: A4_COG_Generator_Worker.cog_generator_sub_worker scheduled__2024-09-27T05:20:00+00:00 map_index=0 [queued]>
[2024-09-27T06:17:08.682+0000] {taskinstance.py:1361} INFO - Starting attempt 1 of 1
[2024-09-27T06:17:08.696+0000] {taskinstance.py:1382} INFO - Executing <Mapped(_PythonDecoratedOperator): cog_generator_sub_worker> on 2024-09-27 05:20:00+00:00
[2024-09-27T06:17:08.702+0000] {standard_task_runner.py:57} INFO - Started process 1961109 to run task
[2024-09-27T06:17:08.710+0000] {standard_task_runner.py:84} INFO - Running: ['airflow', 'tasks', 'run', 'A4_COG_Generator_Worker', 'cog_generator_sub_worker', 'scheduled__2024-09-27T05:20:00+00:00', '--job-id', '104716', '--raw', '--subdir', '/home/ladsadmin/FGICWebApp/Airflow/dags/a4_cog_generator_worker_dag.py', '--cfg-path', '/tmp/tmp2a0pq3uw', '--map-index', '0']
[2024-09-27T06:17:08.714+0000] {standard_task_runner.py:85} INFO - Job 104716: Subtask cog_generator_sub_worker
[2024-09-27T06:17:08.800+0000] {task_command.py:416} INFO - Running <TaskInstance: A4_COG_Generator_Worker.cog_generator_sub_worker scheduled__2024-09-27T05:20:00+00:00 map_index=0 [running]> on host iadsstgapphost01
[2024-09-27T06:17:08.974+0000] {taskinstance.py:1662} INFO - Exporting env vars: AIRFLOW_CTX_DAG_OWNER='airflow' AIRFLOW_CTX_DAG_ID='A4_COG_Generator_Worker' AIRFLOW_CTX_TASK_ID='cog_generator_sub_worker' AIRFLOW_CTX_EXECUTION_DATE='2024-09-27T05:20:00+00:00' AIRFLOW_CTX_TRY_NUMBER='1' AIRFLOW_CTX_DAG_RUN_ID='scheduled__2024-09-27T05:20:00+00:00'
[2024-09-27T06:17:08.975+0000] {a4_cog_generator_worker_dag.py:31} INFO - Cog-Generator worker started its work.
[2024-09-27T06:17:09.290+0000] {_base_logger.py:66} DEBUG - {"worker": "CogGeneratorWorker", "msg": "Checking if the Item is Eligible to Start CogGeneratorWorker.", "level": "DEBUG", "source_data": "UAE_2019_1m.img"}
[2024-09-27T06:17:09.296+0000] {_base_logger.py:66} DEBUG - {"worker": "CogGeneratorWorker", "msg": "Reached at the \u201celigible_item_reader\u201d Method & About to Execute.", "level": "DEBUG", "source_data": "UAE_2019_1m.img"}
[2024-09-27T06:17:09.300+0000] {_base_logger.py:40} INFO - {"worker": "CogGeneratorWorker", "msg": "Well Done!! Item is Eligible to execute CogGeneratorWorker.", "level": "INFO", "source_data": "UAE_2019_1m.img"}
[2024-09-27T06:17:09.307+0000] {_base_logger.py:66} DEBUG - {"worker": "CogGeneratorWorker", "msg": "Now starting CogGeneratorWorker.", "level": "DEBUG", "source_data": "UAE_2019_1m.img"}
[2024-09-27T06:17:09.313+0000] {_base_logger.py:66} DEBUG - {"worker": "CogGeneratorWorker", "msg": "Reached at the 'process_started_worker' Method & About to Execute.", "level": "DEBUG", "source_data": "UAE_2019_1m.img"}
[2024-09-27T06:17:09.315+0000] {_base_logger.py:40} INFO - {"worker": "CogGeneratorWorker", "msg": "Well Done!! CogGeneratorWorker Started.", "level": "INFO", "source_data": "UAE_2019_1m.img"}
[2024-09-27T06:17:09.321+0000] {_base_logger.py:66} DEBUG - {"worker": "CogGeneratorWorker", "msg": "Getting File Path of a File from Source Data Table in Database.", "level": "DEBUG", "source_data": "UAE_2019_1m.img"}
[2024-09-27T06:17:09.324+0000] {_base_logger.py:40} INFO - {"worker": "CogGeneratorWorker", "msg": "Great!! File Path obtained Successfully from Database.", "level": "INFO", "source_data": "UAE_2019_1m.img"}
[2024-09-27T06:17:09.328+0000] {_base_logger.py:66} DEBUG - {"worker": "CogGeneratorWorker", "msg": "Getting Target Data object Related to Source Data form Database.", "level": "DEBUG", "source_data": "UAE_2019_1m.img"}
[2024-09-27T06:17:09.336+0000] {_base_logger.py:66} DEBUG - {"worker": "CogGeneratorWorker", "msg": "Successfully Got Target Data object from Database.", "level": "DEBUG", "source_data": "UAE_2019_1m.img", "target_data": "/home/ladsadmin/share/stgrasterstore/3e092819-0462-4d4d-96bb-95b292d05957_2024-09-26_07-22-49.img"}
[2024-09-27T06:17:09.342+0000] {_base_logger.py:66} DEBUG - {"worker": "CogGeneratorWorker", "msg": "Need to Create COG for 1 Images.", "level": "DEBUG", "source_data": "UAE_2019_1m.img", "target_data": "/home/ladsadmin/share/stgrasterstore/3e092819-0462-4d4d-96bb-95b292d05957_2024-09-26_07-22-49.img"}
[2024-09-27T06:17:09.345+0000] {_base_logger.py:66} DEBUG - {"worker": "CogGeneratorWorker", "msg": "[0] Generating COG Path for file and path is: /home/ladsadmin/mnt/Local_Ingester_Folder/3e092819-0462-4d4d-96bb-95b292d05957_2024-09-26_07-22-49.img", "level": "DEBUG", "source_data": "UAE_2019_1m.img", "target_data": "/home/ladsadmin/share/stgrasterstore/3e092819-0462-4d4d-96bb-95b292d05957_2024-09-26_07-22-49.img"}
[2024-09-27T06:17:09.351+0000] {_base_logger.py:66} DEBUG - {"worker": "CogGeneratorWorker", "msg": "If GENERATE_COG_ON_LOCAL is True then Generate COG on local machine.", "level": "DEBUG", "source_data": "UAE_2019_1m.img", "target_data": "/home/ladsadmin/share/stgrasterstore/3e092819-0462-4d4d-96bb-95b292d05957_2024-09-26_07-22-49.img"}
[2024-09-27T06:17:09.354+0000] {_base_logger.py:66} DEBUG - {"worker": "CogGeneratorWorker", "msg": "Generating COG on Local Machine.", "level": "DEBUG", "source_data": "UAE_2019_1m.img", "target_data": "/home/ladsadmin/share/stgrasterstore/3e092819-0462-4d4d-96bb-95b292d05957_2024-09-26_07-22-49.img"}
[2024-09-27T06:17:09.357+0000] {_base_logger.py:66} DEBUG - {"worker": "CogGeneratorWorker", "msg": "base_path when GENERATE_COG_ON_LOCAL is yes: /home/ladsadmin/mnt/Local_Ingester_Folder", "level": "DEBUG", "source_data": "UAE_2019_1m.img", "target_data": "/home/ladsadmin/share/stgrasterstore/3e092819-0462-4d4d-96bb-95b292d05957_2024-09-26_07-22-49.img"}
[2024-09-27T06:17:09.359+0000] {_base_logger.py:66} DEBUG - {"worker": "CogGeneratorWorker", "msg": "New directory path without month folder: /home/ladsadmin/mnt/Local_Ingester_Folder", "level": "DEBUG", "source_data": "UAE_2019_1m.img", "target_data": "/home/ladsadmin/share/stgrasterstore/3e092819-0462-4d4d-96bb-95b292d05957_2024-09-26_07-22-49.img"}
[2024-09-27T06:17:09.362+0000] {_base_logger.py:66} DEBUG - {"worker": "CogGeneratorWorker", "msg": "Directory already exists: /home/ladsadmin/mnt/Local_Ingester_Folder", "level": "DEBUG", "source_data": "UAE_2019_1m.img", "target_data": "/home/ladsadmin/share/stgrasterstore/3e092819-0462-4d4d-96bb-95b292d05957_2024-09-26_07-22-49.img"}
[2024-09-27T06:17:09.368+0000] {_base_logger.py:66} DEBUG - {"worker": "CogGeneratorWorker", "msg": "Reached at the \u201cconvert_tiff_to_cog\u201d Method & About to Execute.", "level": "DEBUG", "source_data": "UAE_2019_1m.img"}
[2024-09-27T06:17:09.373+0000] {_base_logger.py:66} DEBUG - {"worker": "CogGeneratorWorker", "msg": "Opening tiff file using GDAL. /home/ladsadmin/mnt/Local_Ingester_Folder/3e092819-0462-4d4d-96bb-95b292d05957_2024-09-26_07-22-49.img", "level": "DEBUG", "source_data": "UAE_2019_1m.img"}
[2024-09-27T06:17:09.444+0000] {_base_logger.py:66} DEBUG - {"worker": "CogGeneratorWorker", "msg": "Great!! File Opened Successfully through GDAL.", "level": "DEBUG", "source_data": "UAE_2019_1m.img"}
[2024-09-27T06:17:09.448+0000] {_base_logger.py:66} DEBUG - {"worker": "CogGeneratorWorker", "msg": "Checking description.", "level": "DEBUG", "source_data": "UAE_2019_1m.img"}
[2024-09-27T06:17:09.450+0000] {_base_logger.py:66} DEBUG - {"worker": "CogGeneratorWorker", "msg": "Description from GDAL: /home/ladsadmin/mnt/Local_Ingester_Folder/3e092819-0462-4d4d-96bb-95b292d05957_2024-09-26_07-22-49.img", "level": "DEBUG", "source_data": "UAE_2019_1m.img"}
[2024-09-27T06:17:09.453+0000] {_base_logger.py:66} DEBUG - {"worker": "CogGeneratorWorker", "msg": "Checking file size.", "level": "DEBUG", "source_data": "UAE_2019_1m.img"}
[2024-09-27T06:17:09.456+0000] {_base_logger.py:66} DEBUG - {"worker": "CogGeneratorWorker", "msg": "Extension of Source File Path is: .img", "level": "DEBUG", "source_data": "UAE_2019_1m.img"}
[2024-09-27T06:17:09.459+0000] {_base_logger.py:66} DEBUG - {"worker": "CogGeneratorWorker", "msg": "Base name is: /home/ladsadmin/share/stghot1/UAE_2019_1m", "level": "DEBUG", "source_data": "UAE_2019_1m.img"}
[2024-09-27T06:17:09.462+0000] {_base_logger.py:66} DEBUG - {"worker": "CogGeneratorWorker", "msg": "Filename is: UAE_2019_1m", "level": "DEBUG", "source_data": "UAE_2019_1m.img"}
[2024-09-27T06:17:09.465+0000] {_base_logger.py:66} DEBUG - {"worker": "CogGeneratorWorker", "msg": "Pair tiff paths are: ['/home/ladsadmin/mnt/Local_Ingester_Folder/UAE_2019_1m.ige', '/home/ladsadmin/mnt/Local_Ingester_Folder/UAE_2019_1m.rrd', '/home/ladsadmin/mnt/Local_Ingester_Folder/UAE_2019_1m.rde']", "level": "DEBUG", "source_data": "UAE_2019_1m.img"}
[2024-09-27T06:17:09.468+0000] {_base_logger.py:66} DEBUG - {"worker": "CogGeneratorWorker", "msg": "Total size which contains main source file and its associated pair files: 34871", "level": "DEBUG", "source_data": "UAE_2019_1m.img"}
[2024-09-27T06:17:09.471+0000] {_base_logger.py:66} DEBUG - {"worker": "CogGeneratorWorker", "msg": "File size is less than 4GB.", "level": "DEBUG", "source_data": "UAE_2019_1m.img"}
[2024-09-27T06:17:09.474+0000] {_base_logger.py:40} INFO - {"worker": "CogGeneratorWorker", "msg": "About to Generate COG of a File and  COG Path is: /home/ladsadmin/mnt/Local_Ingester_Folder/3e092819-0462-4d4d-96bb-95b292d05957_2024-09-26_07-22-49_cog.tif", "level": "INFO", "source_data": "UAE_2019_1m.img"}
[2024-09-27T07:53:26.209+0000] {_base_logger.py:66} DEBUG - {"worker": "CogGeneratorWorker", "msg": "output_ds: <osgeo.gdal.Dataset; proxy of <Swig Object of type 'GDALDatasetShadow *' at 0x7f6b131a74b0> >", "level": "DEBUG", "source_data": "UAE_2019_1m.img"}
[2024-09-27T07:53:26.695+0000] {_base_logger.py:118} ERROR - {"worker": "CogGeneratorWorker", "msg": "Oops!! Unfortunatly, Found an Error again while Generating COG file and error is: server closed the connection unexpectedly\n\tThis probably means the server terminated abnormally\n\tbefore or while processing the request.\n and Traceback (most recent call last):\n  File \"/home/ladsadmin/FGICWebApp/venv/lib/python3.10/site-packages/django/db/backends/utils.py\", line 89, in _execute\n    return self.cursor.execute(sql, params)\npsycopg2.OperationalError: server closed the connection unexpectedly\n\tThis probably means the server terminated abnormally\n\tbefore or while processing the request.\n\n\nThe above exception was the direct cause of the following exception:\n\nTraceback (most recent call last):\n  File \"/home/ladsadmin/FGICWebApp/IngestionEngine/workers/cog_generator_worker.py\", line 259, in convert_tiff_to_cog\n    log(\n  File \"/home/ladsadmin/FGICWebApp/IngestionEngine/workers/_base_logger.py\", line 67, in log\n    IngestionLogs.objects.create(\n  File \"/home/ladsadmin/FGICWebApp/venv/lib/python3.10/site-packages/django/db/models/manager.py\", line 87, in manager_method\n    return getattr(self.get_queryset(), name)(*args, **kwargs)\n  File \"/home/ladsadmin/FGICWebApp/venv/lib/python3.10/site-packages/django/db/models/query.py\", line 658, in create\n    obj.save(force_insert=True, using=self.db)\n  File \"/home/ladsadmin/FGICWebApp/venv/lib/python3.10/site-packages/django/db/models/base.py\", line 814, in save\n    self.save_base(\n  File \"/home/ladsadmin/FGICWebApp/venv/lib/python3.10/site-packages/django/db/models/base.py\", line 877, in save_base\n    updated = self._save_table(\n  File \"/home/ladsadmin/FGICWebApp/venv/lib/python3.10/site-packages/django/db/models/base.py\", line 1020, in _save_table\n    results = self._do_insert(\n  File \"/home/ladsadmin/FGICWebApp/venv/lib/python3.10/site-packages/django/db/models/base.py\", line 1061, in _do_insert\n    return manager._insert(\n  File \"/home/ladsadmin/FGICWebApp/venv/lib/python3.10/site-packages/django/db/models/manager.py\", line 87, in manager_method\n    return getattr(self.get_queryset(), name)(*args, **kwargs)\n  File \"/home/ladsadmin/FGICWebApp/venv/lib/python3.10/site-packages/django/db/models/query.py\", line 1805, in _insert\n    return query.get_compiler(using=using).execute_sql(returning_fields)\n  File \"/home/ladsadmin/FGICWebApp/venv/lib/python3.10/site-packages/django/db/models/sql/compiler.py\", line 1822, in execute_sql\n    cursor.execute(sql, params)\n  File \"/home/ladsadmin/FGICWebApp/venv/lib/python3.10/site-packages/django/db/backends/utils.py\", line 102, in execute\n    return super().execute(sql, params)\n  File \"/home/ladsadmin/FGICWebApp/venv/lib/python3.10/site-packages/django/db/backends/utils.py\", line 67, in execute\n    return self._execute_with_wrappers(\n  File \"/home/ladsadmin/FGICWebApp/venv/lib/python3.10/site-packages/django/db/backends/utils.py\", line 80, in _execute_with_wrappers\n    return executor(sql, params, many, context)\n  File \"/home/ladsadmin/FGICWebApp/venv/lib/python3.10/site-packages/django/db/backends/utils.py\", line 84, in _execute\n    with self.db.wrap_database_errors:\n  File \"/home/ladsadmin/FGICWebApp/venv/lib/python3.10/site-packages/django/db/utils.py\", line 91, in __exit__\n    raise dj_exc_value.with_traceback(traceback) from exc_value\n  File \"/home/ladsadmin/FGICWebApp/venv/lib/python3.10/site-packages/django/db/backends/utils.py\", line 89, in _execute\n    return self.cursor.execute(sql, params)\ndjango.db.utils.OperationalError: server closed the connection unexpectedly\n\tThis probably means the server terminated abnormally\n\tbefore or while processing the request.\n\n", "level": "ERROR", "source_data": "UAE_2019_1m.img"}
[2024-09-27T07:53:26.760+0000] {taskinstance.py:1937} ERROR - Task failed with exception
Traceback (most recent call last):
  File "/home/ladsadmin/FGICWebApp/venv/lib/python3.10/site-packages/django/db/backends/utils.py", line 89, in _execute
    return self.cursor.execute(sql, params)
psycopg2.OperationalError: server closed the connection unexpectedly
	This probably means the server terminated abnormally
	before or while processing the request.
The above exception was the direct cause of the following exception:
Traceback (most recent call last):
  File "/home/ladsadmin/FGICWebApp/IngestionEngine/workers/cog_generator_worker.py", line 259, in convert_tiff_to_cog
    log(
  File "/home/ladsadmin/FGICWebApp/IngestionEngine/workers/_base_logger.py", line 67, in log
    IngestionLogs.objects.create(
  File "/home/ladsadmin/FGICWebApp/venv/lib/python3.10/site-packages/django/db/models/manager.py", line 87, in manager_method
    return getattr(self.get_queryset(), name)(*args, **kwargs)
  File "/home/ladsadmin/FGICWebApp/venv/lib/python3.10/site-packages/django/db/models/query.py", line 658, in create
    obj.save(force_insert=True, using=self.db)
  File "/home/ladsadmin/FGICWebApp/venv/lib/python3.10/site-packages/django/db/models/base.py", line 814, in save
    self.save_base(
  File "/home/ladsadmin/FGICWebApp/venv/lib/python3.10/site-packages/django/db/models/base.py", line 877, in save_base
    updated = self._save_table(
  File "/home/ladsadmin/FGICWebApp/venv/lib/python3.10/site-packages/django/db/models/base.py", line 1020, in _save_table
    results = self._do_insert(
  File "/home/ladsadmin/FGICWebApp/venv/lib/python3.10/site-packages/django/db/models/base.py", line 1061, in _do_insert
    return manager._insert(
  File "/home/ladsadmin/FGICWebApp/venv/lib/python3.10/site-packages/django/db/models/manager.py", line 87, in manager_method
    return getattr(self.get_queryset(), name)(*args, **kwargs)
  File "/home/ladsadmin/FGICWebApp/venv/lib/python3.10/site-packages/django/db/models/query.py", line 1805, in _insert
    return query.get_compiler(using=using).execute_sql(returning_fields)
  File "/home/ladsadmin/FGICWebApp/venv/lib/python3.10/site-packages/django/db/models/sql/compiler.py", line 1822, in execute_sql
    cursor.execute(sql, params)
  File "/home/ladsadmin/FGICWebApp/venv/lib/python3.10/site-packages/django/db/backends/utils.py", line 102, in execute
    return super().execute(sql, params)
  File "/home/ladsadmin/FGICWebApp/venv/lib/python3.10/site-packages/django/db/backends/utils.py", line 67, in execute
    return self._execute_with_wrappers(
  File "/home/ladsadmin/FGICWebApp/venv/lib/python3.10/site-packages/django/db/backends/utils.py", line 80, in _execute_with_wrappers
    return executor(sql, params, many, context)
  File "/home/ladsadmin/FGICWebApp/venv/lib/python3.10/site-packages/django/db/backends/utils.py", line 84, in _execute
    with self.db.wrap_database_errors:
  File "/home/ladsadmin/FGICWebApp/venv/lib/python3.10/site-packages/django/db/utils.py", line 91, in __exit__
    raise dj_exc_value.with_traceback(traceback) from exc_value
  File "/home/ladsadmin/FGICWebApp/venv/lib/python3.10/site-packages/django/db/backends/utils.py", line 89, in _execute
    return self.cursor.execute(sql, params)
django.db.utils.OperationalError: server closed the connection unexpectedly
	This probably means the server terminated abnormally
	before or while processing the request.
During handling of the above exception, another exception occurred:
Traceback (most recent call last):
  File "/home/ladsadmin/FGICWebApp/venv/lib/python3.10/site-packages/django/db/backends/base/base.py", line 308, in _cursor
    return self._prepare_cursor(self.create_cursor(name))
  File "/home/ladsadmin/FGICWebApp/venv/lib/python3.10/site-packages/django/utils/asyncio.py", line 26, in inner
    return func(*args, **kwargs)
  File "/home/ladsadmin/FGICWebApp/venv/lib/python3.10/site-packages/django/db/backends/postgresql/base.py", line 330, in create_cursor
    cursor = self.connection.cursor()
psycopg2.InterfaceError: connection already closed
The above exception was the direct cause of the following exception:
Traceback (most recent call last):
  File "/home/ladsadmin/FGICWebApp/venv/lib/python3.10/site-packages/airflow/decorators/base.py", line 221, in execute
    return_value = super().execute(context)
  File "/home/ladsadmin/FGICWebApp/venv/lib/python3.10/site-packages/airflow/operators/python.py", line 192, in execute
    return_value = self.execute_callable()
  File "/home/ladsadmin/FGICWebApp/venv/lib/python3.10/site-packages/airflow/operators/python.py", line 209, in execute_callable
    return self.python_callable(*self.op_args, **self.op_kwargs)
  File "/home/ladsadmin/FGICWebApp/Airflow/dags/a4_cog_generator_worker_dag.py", line 37, in cog_generator_sub_worker
    worker.start(source_data)
  File "/home/ladsadmin/FGICWebApp/IngestionEngine/workers/cog_generator_worker.py", line 588, in start
    self.process_started_worker(source_data)
  File "/home/ladsadmin/FGICWebApp/IngestionEngine/workers/cog_generator_worker.py", line 470, in process_started_worker
    image.IsCOGGenerated = self.convert_tiff_to_cog(
  File "/home/ladsadmin/FGICWebApp/IngestionEngine/workers/cog_generator_worker.py", line 282, in convert_tiff_to_cog
    log(
  File "/home/ladsadmin/FGICWebApp/IngestionEngine/workers/_base_logger.py", line 119, in log
    IngestionLogs.objects.create(
  File "/home/ladsadmin/FGICWebApp/venv/lib/python3.10/site-packages/django/db/models/manager.py", line 87, in manager_method
    return getattr(self.get_queryset(), name)(*args, **kwargs)
  File "/home/ladsadmin/FGICWebApp/venv/lib/python3.10/site-packages/django/db/models/query.py", line 658, in create
    obj.save(force_insert=True, using=self.db)
  File "/home/ladsadmin/FGICWebApp/venv/lib/python3.10/site-packages/django/db/models/base.py", line 814, in save
    self.save_base(
  File "/home/ladsadmin/FGICWebApp/venv/lib/python3.10/site-packages/django/db/models/base.py", line 877, in save_base
    updated = self._save_table(
  File "/home/ladsadmin/FGICWebApp/venv/lib/python3.10/site-packages/django/db/models/base.py", line 1020, in _save_table
    results = self._do_insert(
  File "/home/ladsadmin/FGICWebApp/venv/lib/python3.10/site-packages/django/db/models/base.py", line 1061, in _do_insert
    return manager._insert(
  File "/home/ladsadmin/FGICWebApp/venv/lib/python3.10/site-packages/django/db/models/manager.py", line 87, in manager_method
    return getattr(self.get_queryset(), name)(*args, **kwargs)
  File "/home/ladsadmin/FGICWebApp/venv/lib/python3.10/site-packages/django/db/models/query.py", line 1805, in _insert
    return query.get_compiler(using=using).execute_sql(returning_fields)
  File "/home/ladsadmin/FGICWebApp/venv/lib/python3.10/site-packages/django/db/models/sql/compiler.py", line 1820, in execute_sql
    with self.connection.cursor() as cursor:
  File "/home/ladsadmin/FGICWebApp/venv/lib/python3.10/site-packages/django/utils/asyncio.py", line 26, in inner
    return func(*args, **kwargs)
  File "/home/ladsadmin/FGICWebApp/venv/lib/python3.10/site-packages/django/db/backends/base/base.py", line 330, in cursor
    return self._cursor()
  File "/home/ladsadmin/FGICWebApp/venv/lib/python3.10/site-packages/django/db/backends/base/base.py", line 307, in _cursor
    with self.wrap_database_errors:
  File "/home/ladsadmin/FGICWebApp/venv/lib/python3.10/site-packages/django/db/utils.py", line 91, in __exit__
    raise dj_exc_value.with_traceback(traceback) from exc_value
  File "/home/ladsadmin/FGICWebApp/venv/lib/python3.10/site-packages/django/db/backends/base/base.py", line 308, in _cursor
    return self._prepare_cursor(self.create_cursor(name))
  File "/home/ladsadmin/FGICWebApp/venv/lib/python3.10/site-packages/django/utils/asyncio.py", line 26, in inner
    return func(*args, **kwargs)
  File "/home/ladsadmin/FGICWebApp/venv/lib/python3.10/site-packages/django/db/backends/postgresql/base.py", line 330, in create_cursor
    cursor = self.connection.cursor()
django.db.utils.InterfaceError: connection already closed
[2024-09-27T07:53:27.176+0000] {taskinstance.py:1400} INFO - Marking task as FAILED. dag_id=A4_COG_Generator_Worker, task_id=cog_generator_sub_worker, map_index=0, execution_date=20240927T052000, start_date=20240927T061708, end_date=20240927T075327
[2024-09-27T07:53:27.526+0000] {standard_task_runner.py:104} ERROR - Failed to execute job 104716 for task cog_generator_sub_worker (connection already closed; 1961109)
[2024-09-27T07:53:27.650+0000] {local_task_job_runner.py:228} INFO - Task exited with return code 1
[2024-09-27T07:53:27.889+0000] {taskinstance.py:2778} INFO - 0 downstream tasks scheduled from follow-on schedule check
