iadsstgapphost01
*** Found local files:
***   * Airflow/logs/dag_id=A3_Local_Ingestor_Worker/run_id=scheduled__2024-09-18T10:10:00+00:00/task_id=ingestor_sub_worker/map_index=0/attempt=1.log
[2024-09-18, 11:10:06 UTC] {taskinstance.py:1159} INFO - Dependencies all met for dep_context=non-requeueable deps ti=<TaskInstance: A3_Local_Ingestor_Worker.ingestor_sub_worker scheduled__2024-09-18T10:10:00+00:00 map_index=0 [queued]>
[2024-09-18, 11:10:06 UTC] {taskinstance.py:1159} INFO - Dependencies all met for dep_context=requeueable deps ti=<TaskInstance: A3_Local_Ingestor_Worker.ingestor_sub_worker scheduled__2024-09-18T10:10:00+00:00 map_index=0 [queued]>
[2024-09-18, 11:10:06 UTC] {taskinstance.py:1361} INFO - Starting attempt 1 of 1
[2024-09-18, 11:10:06 UTC] {taskinstance.py:1382} INFO - Executing <Mapped(_PythonDecoratedOperator): ingestor_sub_worker> on 2024-09-18 10:10:00+00:00
[2024-09-18, 11:10:06 UTC] {standard_task_runner.py:57} INFO - Started process 3137358 to run task
[2024-09-18, 11:10:06 UTC] {standard_task_runner.py:84} INFO - Running: ['airflow', 'tasks', 'run', 'A3_Local_Ingestor_Worker', 'ingestor_sub_worker', 'scheduled__2024-09-18T10:10:00+00:00', '--job-id', '85485', '--raw', '--subdir', '/home/ladsadmin/FGICWebApp/Airflow/dags/a3_ingestor_worker_dag.py', '--cfg-path', '/tmp/tmp7xd9y6bb', '--map-index', '0']
[2024-09-18, 11:10:06 UTC] {standard_task_runner.py:85} INFO - Job 85485: Subtask ingestor_sub_worker
[2024-09-18, 11:10:06 UTC] {task_command.py:416} INFO - Running <TaskInstance: A3_Local_Ingestor_Worker.ingestor_sub_worker scheduled__2024-09-18T10:10:00+00:00 map_index=0 [running]> on host iadsstgapphost01
[2024-09-18, 11:10:06 UTC] {taskinstance.py:1662} INFO - Exporting env vars: AIRFLOW_CTX_DAG_OWNER='airflow' AIRFLOW_CTX_DAG_ID='A3_Local_Ingestor_Worker' AIRFLOW_CTX_TASK_ID='ingestor_sub_worker' AIRFLOW_CTX_EXECUTION_DATE='2024-09-18T10:10:00+00:00' AIRFLOW_CTX_TRY_NUMBER='1' AIRFLOW_CTX_DAG_RUN_ID='scheduled__2024-09-18T10:10:00+00:00'
[2024-09-18, 11:10:06 UTC] {a3_ingestor_worker_dag.py:31} INFO - Local Ingester worker started its work.
[2024-09-18, 11:10:07 UTC] {_base_logger.py:66} DEBUG - {"worker": "LocalIngesterWorker", "msg": "Checking if the Item is Eligible to Start LocalIngesterWorker.", "level": "DEBUG", "source_data": "UAE_2019_1m.img"}
[2024-09-18, 11:10:07 UTC] {_base_logger.py:66} DEBUG - {"worker": "LocalIngesterWorker", "msg": "Reached at the 'eligible_item_reader' Method & About to Execute.", "level": "DEBUG", "source_data": "UAE_2019_1m.img"}
[2024-09-18, 11:10:07 UTC] {_base_logger.py:40} INFO - {"worker": "LocalIngesterWorker", "msg": "Well Done!! Item is Eligible to execute LocalIngesterWorker.", "level": "INFO", "source_data": "UAE_2019_1m.img"}
[2024-09-18, 11:10:07 UTC] {_base_logger.py:40} INFO - {"worker": "LocalIngesterWorker", "msg": "Now Starting LocalIngesterWorker.", "level": "INFO", "source_data": "UAE_2019_1m.img"}
[2024-09-18, 11:10:07 UTC] {_base_logger.py:66} DEBUG - {"worker": "LocalIngesterWorker", "msg": "Reached at the 'process_started_worker' Method & About to Execute.", "level": "DEBUG", "source_data": "UAE_2019_1m.img"}
[2024-09-18, 11:10:07 UTC] {_base_logger.py:40} INFO - {"worker": "LocalIngesterWorker", "msg": "Well Done!! LocalIngesterWorker Started.", "level": "INFO", "source_data": "UAE_2019_1m.img"}
[2024-09-18, 11:10:07 UTC] {_base_logger.py:40} INFO - {"worker": "LocalIngesterWorker", "msg": "Obtaining Metadata of a File.", "level": "INFO", "source_data": "UAE_2019_1m.img"}
[2024-09-18, 11:10:07 UTC] {_base_logger.py:66} DEBUG - {"worker": "LocalIngesterWorker", "msg": "Fetching Metadata with Rasterio.", "level": "DEBUG", "source_data": "UAE_2019_1m.img"}
[2024-09-18, 11:10:07 UTC] {_base_logger.py:40} INFO - {"worker": "LocalIngesterWorker", "msg": "Fetching Metadata.", "level": "INFO", "source_data": "UAE_2019_1m.img"}
[2024-09-18, 11:10:07 UTC] {_base_logger.py:66} DEBUG - {"worker": "LocalIngesterWorker", "msg": "Getting Metadata with Rasterio.", "level": "DEBUG", "source_data": "UAE_2019_1m.img"}
[2024-09-18, 11:10:07 UTC] {_base_logger.py:66} DEBUG - {"worker": "LocalIngesterWorker", "msg": "Searching if File exists at Specific Location.", "level": "DEBUG", "source_data": "UAE_2019_1m.img"}
[2024-09-18, 11:10:07 UTC] {_base_logger.py:66} DEBUG - {"worker": "LocalIngesterWorker", "msg": "Rasterio About to Read the Files to Retrieve the Metadata.", "level": "DEBUG", "source_data": "UAE_2019_1m.img"}
[2024-09-18, 11:10:17 UTC] {_base_logger.py:66} DEBUG - {"worker": "LocalIngesterWorker", "msg": "Rasterio Started Reading the Files.", "level": "DEBUG", "source_data": "UAE_2019_1m.img"}
[2024-09-18, 11:10:17 UTC] {_base_logger.py:66} DEBUG - {"worker": "LocalIngesterWorker", "msg": "Checking Raster Dataset whether it has CRS assigned or defined.", "level": "DEBUG", "source_data": "UAE_2019_1m.img"}
[2024-09-18, 11:10:17 UTC] {_base_logger.py:66} DEBUG - {"worker": "LocalIngesterWorker", "msg": "Create a CRS object Using the Information From dataset.crs.", "level": "DEBUG", "source_data": "UAE_2019_1m.img"}
[2024-09-18, 11:10:17 UTC] {_base_logger.py:66} DEBUG - {"worker": "LocalIngesterWorker", "msg": "Checking if the CRS object exists and if it has an EPSG code Associated with it.", "level": "DEBUG", "source_data": "UAE_2019_1m.img"}
[2024-09-18, 11:10:17 UTC] {_base_logger.py:66} DEBUG - {"worker": "LocalIngesterWorker", "msg": "Getting the EPSG code from the CRS object.", "level": "DEBUG", "source_data": "UAE_2019_1m.img"}
[2024-09-18, 11:10:17 UTC] {_base_logger.py:66} DEBUG - {"worker": "LocalIngesterWorker", "msg": "Obtained Number of pixels: 730697", "level": "DEBUG", "source_data": "UAE_2019_1m.img"}
[2024-09-18, 11:10:17 UTC] {_base_logger.py:66} DEBUG - {"worker": "LocalIngesterWorker", "msg": "Obtained Number of layers: 445189", "level": "DEBUG", "source_data": "UAE_2019_1m.img"}
[2024-09-18, 11:10:17 UTC] {_base_logger.py:66} DEBUG - {"worker": "LocalIngesterWorker", "msg": "Obtained Horizontal Resolution: 9.589166666666666e-06", "level": "DEBUG", "source_data": "UAE_2019_1m.img"}
[2024-09-18, 11:10:17 UTC] {_base_logger.py:66} DEBUG - {"worker": "LocalIngesterWorker", "msg": "Transforming extent to EPSG: 4326", "level": "DEBUG", "source_data": "UAE_2019_1m.img"}
[2024-09-18, 11:10:17 UTC] {_base_logger.py:66} DEBUG - {"worker": "LocalIngesterWorker", "msg": "Obtained extent of a file: SRID=4326;POLYGON ((50.62530517578125 22.61449236755208, 57.63208049161458 22.61449236755208, 57.63208049161458 26.88348388671875, 50.62530517578125 26.88348388671875, 50.62530517578125 22.61449236755208)).", "level": "DEBUG", "source_data": "UAE_2019_1m.img"}
[2024-09-18, 11:10:17 UTC] {_base_logger.py:66} DEBUG - {"worker": "LocalIngesterWorker", "msg": "Well Done!! Metadata obtained Successfully from Rasterio: {'EpsgCode': 4326, 'NumPixels': 730697, 'NumLayers': 445189, 'HorizontalResolution': 9.589166666666666e-06, 'Extent': <Polygon object at 0x7f7aeee8ca10>}.", "level": "DEBUG", "source_data": "UAE_2019_1m.img"}
[2024-09-18, 11:10:17 UTC] {_base_logger.py:40} INFO - {"worker": "LocalIngesterWorker", "msg": "Metadata fetched: {'EpsgCode': 4326, 'NumPixels': 730697, 'NumLayers': 445189, 'HorizontalResolution': 9.589166666666666e-06, 'Extent': <Polygon object at 0x7f7aeee8ca10>}.", "level": "INFO", "source_data": "UAE_2019_1m.img", "file": "UAE_2019_1m.img"}
[2024-09-18, 11:10:17 UTC] {_base_logger.py:66} DEBUG - {"worker": "LocalIngesterWorker", "msg": "Getting Target data which is Related to Source Data. ", "level": "DEBUG", "source_data": "UAE_2019_1m.img", "target_data": "/home/ladsadmin/share/stgrasterstore/5b6b2205-59b9-450c-8c11-f01ff2ba8323_2024-09-18_11-05-04.img"}
[2024-09-18, 11:10:17 UTC] {_base_logger.py:66} DEBUG - {"worker": "LocalIngesterWorker", "msg": "Checking if Business Metadata is exists in Database or not.", "level": "DEBUG", "source_data": "UAE_2019_1m.img", "target_data": "/home/ladsadmin/share/stgrasterstore/5b6b2205-59b9-450c-8c11-f01ff2ba8323_2024-09-18_11-05-04.img"}
[2024-09-18, 11:10:17 UTC] {_base_logger.py:66} DEBUG - {"worker": "LocalIngesterWorker", "msg": "Creating new Business Metadata object for a Target Data.", "level": "DEBUG", "source_data": "UAE_2019_1m.img", "target_data": "/home/ladsadmin/share/stgrasterstore/5b6b2205-59b9-450c-8c11-f01ff2ba8323_2024-09-18_11-05-04.img"}
[2024-09-18, 11:10:17 UTC] {_base_logger.py:40} INFO - {"worker": "LocalIngesterWorker", "msg": "Metadata of a File Added in Database Successfully.", "level": "INFO", "source_data": "UAE_2019_1m.img", "target_data": "/home/ladsadmin/share/stgrasterstore/5b6b2205-59b9-450c-8c11-f01ff2ba8323_2024-09-18_11-05-04.img"}
[2024-09-18, 11:10:17 UTC] {_base_logger.py:40} INFO - {"worker": "LocalIngesterWorker", "msg": "Source Data File Path is: /home/ladsadmin/share/stghot1/UAE_2019_1m.img", "level": "INFO", "source_data": "UAE_2019_1m.img", "target_data": "/home/ladsadmin/share/stgrasterstore/5b6b2205-59b9-450c-8c11-f01ff2ba8323_2024-09-18_11-05-04.img"}
[2024-09-18, 11:10:17 UTC] {_base_logger.py:66} DEBUG - {"worker": "LocalIngesterWorker", "msg": "Created Possible Excel and CSV File Paths for Source Data: ['/home/ladsadmin/share/stghot1/UAE_2019_1m_img.xlsx', '/home/ladsadmin/share/stghot1/UAE_2019_1m_img.xls', '/home/ladsadmin/share/stghot1/UAE_2019_1m_img.csv']", "level": "DEBUG", "source_data": "UAE_2019_1m.img", "target_data": "/home/ladsadmin/share/stgrasterstore/5b6b2205-59b9-450c-8c11-f01ff2ba8323_2024-09-18_11-05-04.img"}
[2024-09-18, 11:10:17 UTC] {_base_logger.py:66} DEBUG - {"worker": "LocalIngesterWorker", "msg": "Checking if any of the Excel/CSV file paths exists in the hot folder.", "level": "DEBUG", "source_data": "UAE_2019_1m.img", "target_data": "/home/ladsadmin/share/stgrasterstore/5b6b2205-59b9-450c-8c11-f01ff2ba8323_2024-09-18_11-05-04.img"}
[2024-09-18, 11:10:18 UTC] {_base_logger.py:66} DEBUG - {"worker": "LocalIngesterWorker", "msg": "Checking if we found a Valid Excel/CSV file path.", "level": "DEBUG", "source_data": "UAE_2019_1m.img", "target_data": "/home/ladsadmin/share/stgrasterstore/5b6b2205-59b9-450c-8c11-f01ff2ba8323_2024-09-18_11-05-04.img"}
[2024-09-18, 11:10:18 UTC] {_base_logger.py:92} WARNING - {"worker": "LocalIngesterWorker", "msg": "Oops!! Excel File might not be Exist.", "level": "WARNING", "source_data": "UAE_2019_1m.img", "target_data": "/home/ladsadmin/share/stgrasterstore/5b6b2205-59b9-450c-8c11-f01ff2ba8323_2024-09-18_11-05-04.img"}
[2024-09-18, 11:10:18 UTC] {_base_logger.py:40} INFO - {"worker": "LocalIngesterWorker", "msg": "Starting Copying Process of a File to Destination Folder.", "level": "INFO", "source_data": "UAE_2019_1m.img", "target_data": "/home/ladsadmin/share/stgrasterstore/5b6b2205-59b9-450c-8c11-f01ff2ba8323_2024-09-18_11-05-04.img"}
[2024-09-18, 11:10:18 UTC] {_base_logger.py:66} DEBUG - {"worker": "LocalIngesterWorker", "msg": "Obtaining Source File Path from Source Data Table.", "level": "DEBUG", "source_data": "UAE_2019_1m.img", "target_data": "/home/ladsadmin/share/stgrasterstore/5b6b2205-59b9-450c-8c11-f01ff2ba8323_2024-09-18_11-05-04.img"}
[2024-09-18, 11:10:18 UTC] {_base_logger.py:66} DEBUG - {"worker": "LocalIngesterWorker", "msg": "Extension of Source File Path is: .img", "level": "DEBUG", "source_data": "UAE_2019_1m.img", "target_data": "/home/ladsadmin/share/stgrasterstore/5b6b2205-59b9-450c-8c11-f01ff2ba8323_2024-09-18_11-05-04.img"}
[2024-09-18, 11:10:18 UTC] {_base_logger.py:66} DEBUG - {"worker": "LocalIngesterWorker", "msg": "Checking if extension is related to pair files.", "level": "DEBUG", "source_data": "UAE_2019_1m.img", "target_data": "/home/ladsadmin/share/stgrasterstore/5b6b2205-59b9-450c-8c11-f01ff2ba8323_2024-09-18_11-05-04.img"}
[2024-09-18, 11:10:18 UTC] {_base_logger.py:66} DEBUG - {"worker": "LocalIngesterWorker", "msg": "Base name is: /home/ladsadmin/share/stghot1/UAE_2019_1m", "level": "DEBUG", "source_data": "UAE_2019_1m.img", "target_data": "/home/ladsadmin/share/stgrasterstore/5b6b2205-59b9-450c-8c11-f01ff2ba8323_2024-09-18_11-05-04.img"}
[2024-09-18, 11:10:18 UTC] {_base_logger.py:66} DEBUG - {"worker": "LocalIngesterWorker", "msg": "Filename is: UAE_2019_1m", "level": "DEBUG", "source_data": "UAE_2019_1m.img", "target_data": "/home/ladsadmin/share/stgrasterstore/5b6b2205-59b9-450c-8c11-f01ff2ba8323_2024-09-18_11-05-04.img"}
[2024-09-18, 11:10:18 UTC] {_base_logger.py:66} DEBUG - {"worker": "LocalIngesterWorker", "msg": "Adding pair file to copy 2: /home/ladsadmin/share/stghot1/UAE_2019_1m.ige -> /home/ladsadmin/share/stgrasterstore/UAE_2019_1m.ige", "level": "DEBUG", "source_data": "UAE_2019_1m.img", "target_data": "/home/ladsadmin/share/stgrasterstore/5b6b2205-59b9-450c-8c11-f01ff2ba8323_2024-09-18_11-05-04.img"}
[2024-09-18, 11:10:18 UTC] {_base_logger.py:40} INFO - {"worker": "LocalIngesterWorker", "msg": "Copying files on LOCAL INGESTED FOLDER.", "level": "INFO", "source_data": "UAE_2019_1m.img", "target_data": "/home/ladsadmin/share/stgrasterstore/5b6b2205-59b9-450c-8c11-f01ff2ba8323_2024-09-18_11-05-04.img", "destination_path": "/home/ladsadmin/share/stgrasterstore/5b6b2205-59b9-450c-8c11-f01ff2ba8323_2024-09-18_11-05-04.img"}
[2024-09-18, 11:10:18 UTC] {_base_logger.py:66} DEBUG - {"worker": "LocalIngesterWorker", "msg": "New directory path without month: /home/ladsadmin/mnt/Local_Ingester_Folder", "level": "DEBUG", "source_data": "UAE_2019_1m.img"}
[2024-09-18, 11:10:18 UTC] {_base_logger.py:66} DEBUG - {"worker": "LocalIngesterWorker", "msg": "Local Destination Path is: /home/ladsadmin/mnt/Local_Ingester_Folder/UAE_2019_1m.ige", "level": "DEBUG", "source_data": "UAE_2019_1m.img", "target_data": "/home/ladsadmin/share/stgrasterstore/5b6b2205-59b9-450c-8c11-f01ff2ba8323_2024-09-18_11-05-04.img"}
[2024-09-18, 11:46:00 UTC] {taskinstance.py:1632} ERROR - Received SIGTERM. Terminating subprocesses.
[2024-09-18, 11:46:00 UTC] {taskinstance.py:1632} ERROR - Received SIGTERM. Terminating subprocesses.
[2024-09-18, 11:46:00 UTC] {secrets_masker.py:281} WARNING - Unable to redact 'Received SIGTERM. Terminating subprocesses.', please report this via <https://github.com/apache/airflow/issues>. Error was: AirflowException: Task received SIGTERM signal
[2024-09-18, 11:46:00 UTC] {_base_logger.py:40} INFO - {"worker": "LocalIngesterWorker", "msg": "Copied /home/ladsadmin/share/stghot1/UAE_2019_1m.ige to /home/ladsadmin/mnt/Local_Ingester_Folder/UAE_2019_1m.ige with output: [{'source': '/home/ladsadmin/share/stghot1/UAE_2019_1m.ige', 'destination': '/home/ladsadmin/mnt/Local_Ingester_Folder/UAE_2019_1m.ige', 'error': 'Task received SIGTERM signal'}]", "level": "INFO", "source_data": "UAE_2019_1m.img", "target_data": "/home/ladsadmin/share/stgrasterstore/5b6b2205-59b9-450c-8c11-f01ff2ba8323_2024-09-18_11-05-04.img"}
[2024-09-18, 11:46:00 UTC] {_base_logger.py:118} ERROR - {"worker": "LocalIngesterWorker", "msg": "Error while Getting Destination Path from Target Data: server closed the connection unexpectedly\n\tThis probably means the server terminated abnormally\n\tbefore or while processing the request.\n and Traceback (most recent call last):\n  File \"/home/ladsadmin/FGICWebApp/venv/lib/python3.10/site-packages/django/db/backends/utils.py\", line 89, in _execute\n    return self.cursor.execute(sql, params)\npsycopg2.OperationalError: server closed the connection unexpectedly\n\tThis probably means the server terminated abnormally\n\tbefore or while processing the request.\n\n\nThe above exception was the direct cause of the following exception:\n\nTraceback (most recent call last):\n  File \"/home/ladsadmin/FGICWebApp/IngestionEngine/workers/local_ingester_worker.py\", line 942, in process_started_worker\n    log(\n  File \"/home/ladsadmin/FGICWebApp/IngestionEngine/workers/_base_logger.py\", line 41, in log\n    IngestionLogs.objects.create(\n  File \"/home/ladsadmin/FGICWebApp/venv/lib/python3.10/site-packages/django/db/models/manager.py\", line 87, in manager_method\n    return getattr(self.get_queryset(), name)(*args, **kwargs)\n  File \"/home/ladsadmin/FGICWebApp/venv/lib/python3.10/site-packages/django/db/models/query.py\", line 658, in create\n    obj.save(force_insert=True, using=self.db)\n  File \"/home/ladsadmin/FGICWebApp/venv/lib/python3.10/site-packages/django/db/models/base.py\", line 814, in save\n    self.save_base(\n  File \"/home/ladsadmin/FGICWebApp/venv/lib/python3.10/site-packages/django/db/models/base.py\", line 877, in save_base\n    updated = self._save_table(\n  File \"/home/ladsadmin/FGICWebApp/venv/lib/python3.10/site-packages/django/db/models/base.py\", line 1020, in _save_table\n    results = self._do_insert(\n  File \"/home/ladsadmin/FGICWebApp/venv/lib/python3.10/site-packages/django/db/models/base.py\", line 1061, in _do_insert\n    return manager._insert(\n  File \"/home/ladsadmin/FGICWebApp/venv/lib/python3.10/site-packages/django/db/models/manager.py\", line 87, in manager_method\n    return getattr(self.get_queryset(), name)(*args, **kwargs)\n  File \"/home/ladsadmin/FGICWebApp/venv/lib/python3.10/site-packages/django/db/models/query.py\", line 1805, in _insert\n    return query.get_compiler(using=using).execute_sql(returning_fields)\n  File \"/home/ladsadmin/FGICWebApp/venv/lib/python3.10/site-packages/django/db/models/sql/compiler.py\", line 1822, in execute_sql\n    cursor.execute(sql, params)\n  File \"/home/ladsadmin/FGICWebApp/venv/lib/python3.10/site-packages/django/db/backends/utils.py\", line 102, in execute\n    return super().execute(sql, params)\n  File \"/home/ladsadmin/FGICWebApp/venv/lib/python3.10/site-packages/django/db/backends/utils.py\", line 67, in execute\n    return self._execute_with_wrappers(\n  File \"/home/ladsadmin/FGICWebApp/venv/lib/python3.10/site-packages/django/db/backends/utils.py\", line 80, in _execute_with_wrappers\n    return executor(sql, params, many, context)\n  File \"/home/ladsadmin/FGICWebApp/venv/lib/python3.10/site-packages/django/db/backends/utils.py\", line 84, in _execute\n    with self.db.wrap_database_errors:\n  File \"/home/ladsadmin/FGICWebApp/venv/lib/python3.10/site-packages/django/db/utils.py\", line 91, in __exit__\n    raise dj_exc_value.with_traceback(traceback) from exc_value\n  File \"/home/ladsadmin/FGICWebApp/venv/lib/python3.10/site-packages/django/db/backends/utils.py\", line 89, in _execute\n    return self.cursor.execute(sql, params)\ndjango.db.utils.OperationalError: server closed the connection unexpectedly\n\tThis probably means the server terminated abnormally\n\tbefore or while processing the request.\n\n", "level": "ERROR", "source_data": "UAE_2019_1m.img", "target_data": "/home/ladsadmin/share/stgrasterstore/5b6b2205-59b9-450c-8c11-f01ff2ba8323_2024-09-18_11-05-04.img"}
[2024-09-18, 11:46:00 UTC] {taskinstance.py:1937} ERROR - Task failed with exception
Traceback (most recent call last):
  File "/home/ladsadmin/FGICWebApp/venv/lib/python3.10/site-packages/django/db/backends/utils.py", line 89, in _execute
    return self.cursor.execute(sql, params)
psycopg2.OperationalError: server closed the connection unexpectedly
	This probably means the server terminated abnormally
	before or while processing the request.
The above exception was the direct cause of the following exception:
Traceback (most recent call last):
  File "/home/ladsadmin/FGICWebApp/IngestionEngine/workers/local_ingester_worker.py", line 942, in process_started_worker
    log(
  File "/home/ladsadmin/FGICWebApp/IngestionEngine/workers/_base_logger.py", line 41, in log
    IngestionLogs.objects.create(
  File "/home/ladsadmin/FGICWebApp/venv/lib/python3.10/site-packages/django/db/models/manager.py", line 87, in manager_method
    return getattr(self.get_queryset(), name)(*args, **kwargs)
  File "/home/ladsadmin/FGICWebApp/venv/lib/python3.10/site-packages/django/db/models/query.py", line 658, in create
    obj.save(force_insert=True, using=self.db)
  File "/home/ladsadmin/FGICWebApp/venv/lib/python3.10/site-packages/django/db/models/base.py", line 814, in save
    self.save_base(
  File "/home/ladsadmin/FGICWebApp/venv/lib/python3.10/site-packages/django/db/models/base.py", line 877, in save_base
    updated = self._save_table(
  File "/home/ladsadmin/FGICWebApp/venv/lib/python3.10/site-packages/django/db/models/base.py", line 1020, in _save_table
    results = self._do_insert(
  File "/home/ladsadmin/FGICWebApp/venv/lib/python3.10/site-packages/django/db/models/base.py", line 1061, in _do_insert
    return manager._insert(
  File "/home/ladsadmin/FGICWebApp/venv/lib/python3.10/site-packages/django/db/models/manager.py", line 87, in manager_method
    return getattr(self.get_queryset(), name)(*args, **kwargs)
  File "/home/ladsadmin/FGICWebApp/venv/lib/python3.10/site-packages/django/db/models/query.py", line 1805, in _insert
    return query.get_compiler(using=using).execute_sql(returning_fields)
  File "/home/ladsadmin/FGICWebApp/venv/lib/python3.10/site-packages/django/db/models/sql/compiler.py", line 1822, in execute_sql
    cursor.execute(sql, params)
  File "/home/ladsadmin/FGICWebApp/venv/lib/python3.10/site-packages/django/db/backends/utils.py", line 102, in execute
    return super().execute(sql, params)
  File "/home/ladsadmin/FGICWebApp/venv/lib/python3.10/site-packages/django/db/backends/utils.py", line 67, in execute
    return self._execute_with_wrappers(
  File "/home/ladsadmin/FGICWebApp/venv/lib/python3.10/site-packages/django/db/backends/utils.py", line 80, in _execute_with_wrappers
    return executor(sql, params, many, context)
  File "/home/ladsadmin/FGICWebApp/venv/lib/python3.10/site-packages/django/db/backends/utils.py", line 84, in _execute
    with self.db.wrap_database_errors:
  File "/home/ladsadmin/FGICWebApp/venv/lib/python3.10/site-packages/django/db/utils.py", line 91, in __exit__
    raise dj_exc_value.with_traceback(traceback) from exc_value
  File "/home/ladsadmin/FGICWebApp/venv/lib/python3.10/site-packages/django/db/backends/utils.py", line 89, in _execute
    return self.cursor.execute(sql, params)
django.db.utils.OperationalError: server closed the connection unexpectedly
	This probably means the server terminated abnormally
	before or while processing the request.
During handling of the above exception, another exception occurred:
Traceback (most recent call last):
  File "/home/ladsadmin/FGICWebApp/venv/lib/python3.10/site-packages/django/db/backends/base/base.py", line 308, in _cursor
    return self._prepare_cursor(self.create_cursor(name))
  File "/home/ladsadmin/FGICWebApp/venv/lib/python3.10/site-packages/django/utils/asyncio.py", line 26, in inner
    return func(*args, **kwargs)
  File "/home/ladsadmin/FGICWebApp/venv/lib/python3.10/site-packages/django/db/backends/postgresql/base.py", line 330, in create_cursor
    cursor = self.connection.cursor()
psycopg2.InterfaceError: connection already closed
The above exception was the direct cause of the following exception:
Traceback (most recent call last):
  File "/home/ladsadmin/FGICWebApp/venv/lib/python3.10/site-packages/airflow/decorators/base.py", line 221, in execute
    return_value = super().execute(context)
  File "/home/ladsadmin/FGICWebApp/venv/lib/python3.10/site-packages/airflow/operators/python.py", line 192, in execute
    return_value = self.execute_callable()
  File "/home/ladsadmin/FGICWebApp/venv/lib/python3.10/site-packages/airflow/operators/python.py", line 209, in execute_callable
    return self.python_callable(*self.op_args, **self.op_kwargs)
  File "/home/ladsadmin/FGICWebApp/Airflow/dags/a3_ingestor_worker_dag.py", line 37, in ingestor_sub_worker
    worker.start(source_data)
  File "/home/ladsadmin/FGICWebApp/IngestionEngine/workers/local_ingester_worker.py", line 1450, in start
    self.process_started_worker(source_data)
  File "/home/ladsadmin/FGICWebApp/IngestionEngine/workers/local_ingester_worker.py", line 1063, in process_started_worker
    log(
  File "/home/ladsadmin/FGICWebApp/IngestionEngine/workers/_base_logger.py", line 119, in log
    IngestionLogs.objects.create(
  File "/home/ladsadmin/FGICWebApp/venv/lib/python3.10/site-packages/django/db/models/manager.py", line 87, in manager_method
    return getattr(self.get_queryset(), name)(*args, **kwargs)
  File "/home/ladsadmin/FGICWebApp/venv/lib/python3.10/site-packages/django/db/models/query.py", line 658, in create
    obj.save(force_insert=True, using=self.db)
  File "/home/ladsadmin/FGICWebApp/venv/lib/python3.10/site-packages/django/db/models/base.py", line 814, in save
    self.save_base(
  File "/home/ladsadmin/FGICWebApp/venv/lib/python3.10/site-packages/django/db/models/base.py", line 877, in save_base
    updated = self._save_table(
  File "/home/ladsadmin/FGICWebApp/venv/lib/python3.10/site-packages/django/db/models/base.py", line 1020, in _save_table
    results = self._do_insert(
  File "/home/ladsadmin/FGICWebApp/venv/lib/python3.10/site-packages/django/db/models/base.py", line 1061, in _do_insert
    return manager._insert(
  File "/home/ladsadmin/FGICWebApp/venv/lib/python3.10/site-packages/django/db/models/manager.py", line 87, in manager_method
    return getattr(self.get_queryset(), name)(*args, **kwargs)
  File "/home/ladsadmin/FGICWebApp/venv/lib/python3.10/site-packages/django/db/models/query.py", line 1805, in _insert
    return query.get_compiler(using=using).execute_sql(returning_fields)
  File "/home/ladsadmin/FGICWebApp/venv/lib/python3.10/site-packages/django/db/models/sql/compiler.py", line 1820, in execute_sql
    with self.connection.cursor() as cursor:
  File "/home/ladsadmin/FGICWebApp/venv/lib/python3.10/site-packages/django/utils/asyncio.py", line 26, in inner
    return func(*args, **kwargs)
  File "/home/ladsadmin/FGICWebApp/venv/lib/python3.10/site-packages/django/db/backends/base/base.py", line 330, in cursor
    return self._cursor()
  File "/home/ladsadmin/FGICWebApp/venv/lib/python3.10/site-packages/django/db/backends/base/base.py", line 307, in _cursor
    with self.wrap_database_errors:
  File "/home/ladsadmin/FGICWebApp/venv/lib/python3.10/site-packages/django/db/utils.py", line 91, in __exit__
    raise dj_exc_value.with_traceback(traceback) from exc_value
  File "/home/ladsadmin/FGICWebApp/venv/lib/python3.10/site-packages/django/db/backends/base/base.py", line 308, in _cursor
    return self._prepare_cursor(self.create_cursor(name))
  File "/home/ladsadmin/FGICWebApp/venv/lib/python3.10/site-packages/django/utils/asyncio.py", line 26, in inner
    return func(*args, **kwargs)
  File "/home/ladsadmin/FGICWebApp/venv/lib/python3.10/site-packages/django/db/backends/postgresql/base.py", line 330, in create_cursor
    cursor = self.connection.cursor()
django.db.utils.InterfaceError: connection already closed
[2024-09-18, 11:46:00 UTC] {taskinstance.py:1400} INFO - Marking task as FAILED. dag_id=A3_Local_Ingestor_Worker, task_id=ingestor_sub_worker, map_index=0, execution_date=20240918T101000, start_date=20240918T111006, end_date=20240918T114600
[2024-09-18, 11:46:01 UTC] {local_task_job_runner.py:115} ERROR - Received SIGTERM. Terminating subprocesses
[2024-09-18, 11:46:01 UTC] {process_utils.py:131} INFO - Sending 15 to group 3137358. PIDs of all processes in the group: [3137358]
[2024-09-18, 11:46:01 UTC] {process_utils.py:86} INFO - Sending the signal 15 to group 3137358
[2024-09-18, 11:46:02 UTC] {taskinstance.py:1632} ERROR - Received SIGTERM. Terminating subprocesses.
[2024-09-18, 11:46:02 UTC] {standard_task_runner.py:104} ERROR - Failed to execute job 85485 for task ingestor_sub_worker (Task received SIGTERM signal; 3137358)
[2024-09-18, 11:46:02 UTC] {process_utils.py:79} INFO - Process psutil.Process(pid=3137358, status='terminated', exitcode=1, started='11:10:05') (3137358) terminated with exit code 1
[2024-09-18, 11:46:02 UTC] {local_task_job_runner.py:228} INFO - Task exited with return code 143
[2024-09-18, 11:46:02 UTC] {taskinstance.py:2778} INFO - 0 downstream tasks scheduled from follow-on schedule check




+++++++++++++++++++++++++++++++++++++++++++++++++++++++++++++++++++++++++++++++++++++++++++++++++++++++++++++++++++++++++++++++++++++++++++++++++++++
ATTEMPT 2

iadsstgapphost01
*** Found local files:
***   * Airflow/logs/dag_id=A3_Local_Ingestor_Worker/run_id=scheduled__2024-09-18T10:10:00+00:00/task_id=ingestor_sub_worker/map_index=0/attempt=2.log
[2024-09-18, 11:47:12 UTC] {taskinstance.py:1159} INFO - Dependencies all met for dep_context=non-requeueable deps ti=<TaskInstance: A3_Local_Ingestor_Worker.ingestor_sub_worker scheduled__2024-09-18T10:10:00+00:00 map_index=0 [queued]>
[2024-09-18, 11:47:12 UTC] {taskinstance.py:1159} INFO - Dependencies all met for dep_context=requeueable deps ti=<TaskInstance: A3_Local_Ingestor_Worker.ingestor_sub_worker scheduled__2024-09-18T10:10:00+00:00 map_index=0 [queued]>
[2024-09-18, 11:47:12 UTC] {taskinstance.py:1361} INFO - Starting attempt 2 of 1
[2024-09-18, 11:47:12 UTC] {taskinstance.py:1382} INFO - Executing <Mapped(_PythonDecoratedOperator): ingestor_sub_worker> on 2024-09-18 10:10:00+00:00
[2024-09-18, 11:47:12 UTC] {standard_task_runner.py:57} INFO - Started process 3158518 to run task
[2024-09-18, 11:47:12 UTC] {standard_task_runner.py:84} INFO - Running: ['airflow', 'tasks', 'run', 'A3_Local_Ingestor_Worker', 'ingestor_sub_worker', 'scheduled__2024-09-18T10:10:00+00:00', '--job-id', '85529', '--raw', '--subdir', '/home/ladsadmin/FGICWebApp/Airflow/dags/a3_ingestor_worker_dag.py', '--cfg-path', '/tmp/tmp0905ulyv', '--map-index', '0']
[2024-09-18, 11:47:12 UTC] {standard_task_runner.py:85} INFO - Job 85529: Subtask ingestor_sub_worker
[2024-09-18, 11:47:12 UTC] {task_command.py:416} INFO - Running <TaskInstance: A3_Local_Ingestor_Worker.ingestor_sub_worker scheduled__2024-09-18T10:10:00+00:00 map_index=0 [running]> on host iadsstgapphost01
[2024-09-18, 11:47:12 UTC] {taskinstance.py:1662} INFO - Exporting env vars: AIRFLOW_CTX_DAG_OWNER='airflow' AIRFLOW_CTX_DAG_ID='A3_Local_Ingestor_Worker' AIRFLOW_CTX_TASK_ID='ingestor_sub_worker' AIRFLOW_CTX_EXECUTION_DATE='2024-09-18T10:10:00+00:00' AIRFLOW_CTX_TRY_NUMBER='2' AIRFLOW_CTX_DAG_RUN_ID='scheduled__2024-09-18T10:10:00+00:00'
[2024-09-18, 11:47:12 UTC] {a3_ingestor_worker_dag.py:31} INFO - Local Ingester worker started its work.
[2024-09-18, 11:47:13 UTC] {_base_logger.py:66} DEBUG - {"worker": "LocalIngesterWorker", "msg": "Checking if the Item is Eligible to Start LocalIngesterWorker.", "level": "DEBUG", "source_data": "UAE_2019_1m.img"}
[2024-09-18, 11:47:13 UTC] {_base_logger.py:66} DEBUG - {"worker": "LocalIngesterWorker", "msg": "Reached at the 'eligible_item_reader' Method & About to Execute.", "level": "DEBUG", "source_data": "UAE_2019_1m.img"}
[2024-09-18, 11:47:13 UTC] {_base_logger.py:92} WARNING - {"worker": "LocalIngesterWorker", "msg": "Oops!!.Not an Eligible Item & item InProgress or might be Already Processed.", "level": "WARNING", "source_data": "UAE_2019_1m.img"}
[2024-09-18, 11:47:13 UTC] {python.py:194} INFO - Done. Returned value was: None
[2024-09-18, 11:47:13 UTC] {taskinstance.py:1400} INFO - Marking task as SUCCESS. dag_id=A3_Local_Ingestor_Worker, task_id=ingestor_sub_worker, map_index=0, execution_date=20240918T101000, start_date=20240918T114712, end_date=20240918T114713
[2024-09-18, 11:47:13 UTC] {local_task_job_runner.py:228} INFO - Task exited with return code 0
[2024-09-18, 11:47:13 UTC] {taskinstance.py:2778} INFO - 0 downstream tasks scheduled from follow-on schedule check